Workbook

Sheet Instruções
A1: Respostas das entrevistas: TOPA, Totem por Assinatura
A2: ACH2008 - Empreendedorismo em Informática, turma T94
A4: Como preencher
A5: 1 | B5: Cada integrante preenche as suas 15 linhas na aba Respostas; o nome e o número já estão lá (células cinza, não editar).
A6: 2 | B6: Preencha a Data de cada entrevista: é ela que conta a entrevista como feita na aba Resumo.
A7: 3 | B7: Colunas com lista: escolha no menu da célula. Escalas (P2 e P9): número inteiro de 1 a 5.
A8: 4 | B8: Perguntas abertas: anote com as palavras da pessoa. Passe o mouse no cabeçalho para ver a pergunta completa.
A9: 5 | B9: Não registre nome, telefone, e-mail ou foto do entrevistado: este arquivo fica num repositório público.
A10: 6 | B10: A aba Resumo é calculada sozinha a partir das respostas; não digite nada nela.
A12: Roteiro
A13: Nº | B13: Tela | C13: Pergunta | D13: Resposta
A14: 1 | B14: 1. Cardápio | C14: Olhando essa tela, você saberia fazer um pedido sozinho, sem ajuda? | D14: Sim, Com dúvida ou Não
A15: 2 | B15: 1. Cardápio | C15: Esse totem resolveria a espera ou o atendimento que você costuma enfrentar nesses lugares? 1 (nada) a 5 (totalmente). | D15: Número de 1 a 5
A16: 3 | B16: 1. Cardápio | C16: A "sugestão para você" ajuda ou incomoda? Como você se sentiria sabendo que ela é feita por uma câmera no aparelho? Anotar a reação espontânea. | D16: Texto livre
A17: 4 | B17: 2. Pagamento | C17: Você pagaria por aqui em vez de ir ao caixa? Por quê (ou por que não)? | D17: Sim ou Não, e o motivo
A18: 5 | B18: 2. Pagamento | C18: O que te deixaria inseguro ao pagar nesse totem? Anotar confiança, medo de erro ou falta de recibo. | D18: Texto livre
A19: 6 | B19: 2. Pagamento | C19: Você pagaria mais caro (ex.: R$ 1 a mais) por essa comodidade, ou só usaria se fosse igual ao caixa? | D19: Sim, Só se igual ou Não
A20: 7 | B20: 3. Fila cheia | C20: Se a fila estivesse grande, você pediria pelo próprio celular ou esperaria o totem? Por quê? | D20: Celular ou Totem, e o motivo
A21: 8 | B21: 3. Fila cheia | C21: Escanear ou aproximar o celular sem baixar app é tranquilo para você? O que travaria? | D21: Sim ou Não, e o que travaria
A22: 9 | B22: 3. Fila cheia | C22: No geral: você usaria esse totem no lugar do caixa? Pergunte o motivo da nota. | D22: Número de 1 a 5, e o motivo
A24: Exemplo de linha preenchida (fictício, só para mostrar o formato)
B25: Coluna | C25: Exemplo
B26: Entrevistador | C26: Kauã Lima de Souza
B27: Nº | C27: 1
B28: Data | C28: 46294
B29: Local | C29: Padaria do bairro
B30: P1 Pede sozinho? | C30: Sim
B31: P2 Resolve a espera (1 a 5) | C31: 4
B32: P3 Sugestão e câmera | C32: A sugestão ajuda, mas a câmera incomoda um pouco
B33: P4 Pagaria no totem? | C33: Sim
B34: P4 Por quê | C34: É mais rápido que a fila do caixa
B35: P5 O que deixaria inseguro | C35: Não sair comprovante impresso
B36: P6 Pagaria mais caro? | C36: Só se igual
B37: P7 Celular ou totem? | C37: Celular
B38: P7 Por quê | C38: Não quer esperar em pé
B39: P8 Sem app é tranquilo? | C39: Sim
B40: P8 O que travaria | C40: Internet do celular ruim
B41: P9 Usaria no lugar do caixa (1 a 5) | C41: 4
B42: P9 Motivo da nota | C42: Usaria no pico; com a loja vazia prefere o atendente
B43: Observações

Sheet Respostas
A1: Entrevista | E1: Tela 1: Cardápio | H1: Tela 2: Pagamento | L1: Tela 3: Fila cheia | R1: Geral
A2: Entrevistador | B2: Nº | C2: Data | D2: Local | E2: P1 Pede sozinho? | F2: P2 Resolve a espera (1 a 5) | G2: P3 Sugestão e câmera | H2: P4 Pagaria no totem? | I2: P4 Por quê | J2: P5 O que deixaria inseguro | K2: P6 Pagaria mais caro? | L2: P7 Celular ou totem? | M2: P7 Por quê | N2: P8 Sem app é tranquilo? | O2: P8 O que travaria | P2: P9 Usaria no lugar do caixa (1 a 5) | Q2: P9 Motivo da nota | R2: Observações
A3: Kauã Lima de Souza | B3: 1
A4: Kauã Lima de Souza | B4: 2
A5: Kauã Lima de Souza | B5: 3
A6: Kauã Lima de Souza | B6: 4
A7: Kauã Lima de Souza | B7: 5
A8: Kauã Lima de Souza | B8: 6
A9: Kauã Lima de Souza | B9: 7
A10: Kauã Lima de Souza | B10: 8
A11: Kauã Lima de Souza | B11: 9
A12: Kauã Lima de Souza | B12: 10
A13: Kauã Lima de Souza | B13: 11
A14: Kauã Lima de Souza | B14: 12
... A77: Victor Yodono | B77: 15

Sheet Resumo
A1: Resumo das entrevistas (calculado a partir da aba Respostas)
A3: Andamento
A4: Entrevistador | B4: Feitas | C4: Meta | D4: % da meta
A5: Kauã Lima de Souza | B5: =SUMPRODUCT((Respostas!$A$3:$A$77=A5)*(Respostas!$C$3:$C$77<>"")) | C5: 15 | D5: =IFERROR(B5/C5,0)
A6: Kevin Rodrigues Nunes | B6: =SUMPRODUCT((Respostas!$A$3:$A$77=A6)*(Respostas!$C$3:$C$77<>"")) | C6: 15 | D6: =IFERROR(B6/C6,0)
A7: Luiz Felipe Couto de Souza | B7: =SUMPRODUCT((Respostas!$A$3:$A$77=A7)*(Respostas!$C$3:$C$77<>"")) | C7: 15 | D7: =IFERROR(B7/C7,0)
A8: Renan Biruel Uema | B8: =SUMPRODUCT((Respostas!$A$3:$A$77=A8)*(Respostas!$C$3:$C$77<>"")) | C8: 15 | D8: =IFERROR(B8/C8,0)
A9: Victor Yodono | B9: =SUMPRODUCT((Respostas!$A$3:$A$77=A9)*(Respostas!$C$3:$C$77<>"")) | C9: 15 | D9: =IFERROR(B9/C9,0)
A10: Grupo | B10: =SUM(B5:B9) | C10: =SUM(C5:C9) | D10: =IFERROR(B10/C10,0)
A12: P1. Pede sozinho, sem ajuda? (tela 1)
A13: Resposta | B13: Entrevistas | C13: % das respostas
A14: Sim | B14: =COUNTIF(Respostas!$E$3:$E$77,"Sim") | C14: =IFERROR(B14/SUM($B$14:$B$16),0)
A15: Com dúvida | B15: =COUNTIF(Respostas!$E$3:$E$77,"Com dúvida") | C15: =IFERROR(B15/SUM($B$14:$B$16),0)
A16: Não | B16: =COUNTIF(Respostas!$E$3:$E$77,"Não") | C16: =IFERROR(B16/SUM($B$14:$B$16),0)
A17: Total | B17: =SUM(B14:B16) | C17: =IF(B17=0,0,1)
A19: P2. O totem resolveria a espera? (tela 1)
A20: Média (1 a 5) | B20: =IF(COUNT(Respostas!$F$3:$F$77)=0,"-",AVERAGE(Respostas!$F$3:$F$77))
A21: Nota | B21: Entrevistas | C21: % das respostas
A22: 1 | B22: =COUNTIF(Respostas!$F$3:$F$77,1) | C22: =IFERROR(B22/SUM($B$22:$B$26),0)
A23: 2 | B23: =COUNTIF(Respostas!$F$3:$F$77,2) | C23: =IFERROR(B23/SUM($B$22:$B$26),0)
A24: 3 | B24: =COUNTIF(Respostas!$F$3:$F$77,3) | C24: =IFERROR(B24/SUM($B$22:$B$26),0)
A25: 4 | B25: =COUNTIF(Respostas!$F$3:$F$77,4) | C25: =IFERROR(B25/SUM($B$22:$B$26),0)
A26: 5 | B26: =COUNTIF(Respostas!$F$3:$F$77,5) | C26: =IFERROR(B26/SUM($B$22:$B$26),0)
A28: P4. Pagaria no totem em vez do caixa? (tela 2)
A29: Resposta | B29: Entrevistas | C29: % das respostas
A30: Sim | B30: =COUNTIF(Respostas!$H$3:$H$77,"Sim") | C30: =IFERROR(B30/SUM($B$30:$B$31),0)
A31: Não | B31: =COUNTIF(Respostas!$H$3:$H$77,"Não") | C31: =IFERROR(B31/SUM($B$30:$B$31),0)
A32: Total | B32: =SUM(B30:B31) | C32: =IF(B32=0,0,1)
A34: P6. Pagaria mais caro pela comodidade? (tela 2)
A35: Resposta | B35: Entrevistas | C35: % das respostas
A36: Sim | B36: =COUNTIF(Respostas!$K$3:$K$77,"Sim") | C36: =IFERROR(B36/SUM($B$36:$B$38),0)
A37: Só se igual | B37: =COUNTIF(Respostas!$K$3:$K$77,"Só se igual") | C37: =IFERROR(B37/SUM($B$36:$B$38),0)
A38: Não | B38: =COUNTIF(Respostas!$K$3:$K$77,"Não") | C38: =IFERROR(B38/SUM($B$36:$B$38),0)
A39: Total | B39: =SUM(B36:B38) | C39: =IF(B39=0,0,1)
A41: P7. Com fila, celular ou totem? (tela 3)
A42: Resposta | B42: Entrevistas | C42: % das respostas
A43: Celular | B43: =COUNTIF(Respostas!$L$3:$L$77,"Celular") | C43: =IFERROR(B43/SUM($B$43:$B$44),0)
A44: Totem | B44: =COUNTIF(Respostas!$L$3:$L$77,"Totem") | C44: =IFERROR(B44/SUM($B$43:$B$44),0)
A45: Total | B45: =SUM(B43:B44) | C45: =IF(B45=0,0,1)
A47: P8. Escanear sem baixar app é tranquilo? (tela 3)
...
